Workbook

Sheet Load & IP
T1: Tire size / Pattern | U1: : | V1: 12.00R24 18 L317 | W1: Speed Symbol | AD1: Variasi Kapasitas Pembebanan (%) | AJ1: Kompensasi Tekanan Angin %
K2: Total Load | L2: : | M2: 50 | T2: Load Index | U2: : | V2: =+VLOOKUP(V1,Data!$B$2:$D$50,2,FALSE) -> 4000 | W2: =+VLOOKUP(V1,Data!$B$2:$E$50,4,FALSE) -> G | AD2: Simbol Kecepatan
Q3: I/P by ETRTO | T3: Ave. Speed | U3: : | V3: 30 | X3: Possibility Tire Damage by : | AD3: F | AE3: G | AF3: J | AG3: K | AH3: L | AI3: M
K4: Load Distribution | O4: Load/Tire | T4: STD I/P | U4: : | V4: =+VLOOKUP(V1,Data!$B$2:$E$30,3,FALSE) -> 124 | AC4: 0 | AD4: =+$V$2*Data!I2 -> 10000 | AE4: =+$V$2*Data!J2 -> 10000 | AF4: =+$V$2*Data!K2 -> 10000 | AG4: =+$V$2*Data!L2 -> 10000 | AH4: =+$V$2*Data!M2 -> 10000 | AI4: =+$V$2*Data!N2 -> 10000 | AJ4: =+$V$4*Data!O2 -> 173.6
T5: Result I/P | V5: Result Load | X5: I/P | Z5: Load | AC5: 5 | AD5: =+$V$2*Data!I3 -> 8400 | AE5: =+$V$2*Data!J3 -> 8400 | AF5: =+$V$2*Data!K3 -> 8400 | AG5: =+$V$2*Data!L3 -> 8400 | AH5: =+$V$2*Data!M3 -> 8400 | AI5: =+$V$2*Data!N3 -> 8400 | AJ5: =+$V$4*Data!O3 -> 173.6
K6: 0.13 | L6: : | M6: =+K6*$M$2 -> 6.5 | O6: =+M6/2*1000 -> 3250 | Q6: =+((O6/$V$2)^1.25)*$V$4 -> 95.653507 | T6: =IF(Q6>=$V$4*110%,"CONSULT TO BS","OK") -> OK | V6: =IF(O6>=$V$2*1.15,"Over Load","OK") -> OK | X6: =IF(Q6<=$V$4*110%,"OK",((Q6-$V$4)/$V$4)) -> OK | Z6: =IF(O6<=$V$2*115%,"OK",((O6-$V$2)/$V$2)) -> OK | AC6: 10 | AD6: =+$V$2*Data!I4 -> 7200 | AE6: =+$V$2*Data!J4 -> 7200 | AF6: =+$V$2*Data!K4 -> 7200 | AG6: =+$V$2*Data!L4 -> 7200 | AH6: =+$V$2*Data!M4 -> 7200 | AI6: =+$V$2*Data!N4 -> 7200 | AJ6: =+$V$4*Data!O4 -> 161.2
AC7: 15 | AD7: =+$V$2*Data!I5 -> 6600 | AE7: =+$V$2*Data!J5 -> 6600 | AF7: =+$V$2*Data!K5 -> 6600 | AG7: =+$V$2*Data!L5 -> 6600 | AH7: =+$V$2*Data!M5 -> 6600 | AI7: =+$V$2*Data!N5 -> 6600 | AJ7: =+$V$4*Data!O5 -> 155
AC8: 20 | AD8: =+$V$2*Data!I6 -> 6000 | AE8: =+$V$2*Data!J6 -> 6000 | AF8: =+$V$2*Data!K6 -> 6000 | AG8: =+$V$2*Data!L6 -> 6000 | AH8: =+$V$2*Data!M6 -> 6000 | AI8: =+$V$2*Data!N6 -> 6000 | AJ8: =+$V$4*Data!O6 -> 150.04
K9: 0.13 | L9: : | M9: =+K9*$M$2 -> 6.5 | O9: =+M9/2*1000 -> 3250 | Q9: =+((O9/$V$2)^1.25)*$V$4 -> 95.653507 | T9: =IF(Q9>=$V$4*110%,"CONSULT TO BS","OK") -> OK | V9: =IF(O9>=$V$2*1.15,"Over Load","OK") -> OK | X9: =IF(Q9<=$V$4*110%,"OK",((Q9-$V$4)/$V$4)) -> OK | Z9: =IF(O9<=$V$2*115%,"OK",((O9-$V$2)/$V$2)) -> OK | AC9: 25 | AD9: =+$V$2*Data!I7 -> 5400 | AE9: =+$V$2*Data!J7 -> 5400 | AF9: =+$V$2*Data!K7 -> 5400 | AG9: =+$V$2*Data!L7 -> 5400 | AH9: =+$V$2*Data!M7 -> 5400 | AI9: =+$V$2*Data!N7 -> 5400 | AJ9: =+$V$4*Data!O7 -> 145.08
AC10: 30 | AD10: =+$V$2*Data!I8 -> 5000 | AE10: =+$V$2*Data!J8 -> 5000 | AF10: =+$V$2*Data!K8 -> 5000 | AG10: =+$V$2*Data!L8 -> 5000 | AH10: =+$V$2*Data!M8 -> 5000 | AI10: =+$V$2*Data!N8 -> 5000 | AJ10: =+$V$4*Data!O8 -> 140.12
AC11: 35 | AD11: =+$V$2*Data!I9 -> 4760 | AE11: =+$V$2*Data!J9 -> 4760 | AF11: =+$V$2*Data!K9 -> 4760 | AG11: =+$V$2*Data!L9 -> 4760 | AH11: =+$V$2*Data!M9 -> 4760 | AI11: =+$V$2*Data!N9 -> 4760 | AJ11: =+$V$4*Data!O9 -> 137.64
AC12: 40 | AD12: =+$V$2*Data!I10 -> 4600 | AE12: =+$V$2*Data!J10 -> 4600 | AF12: =+$V$2*Data!K10 -> 4600 | AG12: =+$V$2*Data!L10 -> 4600 | AH12: =+$V$2*Data!M10 -> 4600 | AI12: =+$V$2*Data!N10 -> 4600 | AJ12: =+$V$4*Data!O10 -> 136.4
K13: 0.258 | L13: : | M13: =+K13*$M$2 -> 12.9 | O13: =+M13/4*1000 -> 3225 | Q13: =+((O13/$V$2)^1.25)*$V$4 -> 94.734648 | T13: =IF(Q13>=$V$4*110%,"CONSULT TO BS","OK") -> OK | V13: =IF(O13>=$V$2*1.15,"Over Load","OK") -> OK | X13: =IF(Q13<=$V$4*110%,"OK",((Q13-$V$4)/$V$4)) -> OK | Z13: =IF(O13<=$V$2*115%,"OK",((O13-$V$2)/$V$2)) -> OK | AC13: 45 | AD13: =+$V$2*Data!I11 -> 4520 | AE13: =+$V$2*Data!J11 -> 4520 | AF13: =+$V$2*Data!K11 -> 4520 | AG13: =+$V$2*Data!L11 -> 4520 | AH13: =+$V$2*Data!M11 -> 4520 | AI13: =+$V$2*Data!N11 -> 4520 | AJ13: =+$V$4*Data!O11 -> 135.16
AC14: 50 | AD14: =+$V$2*Data!I12 -> 4480 | AE14: =+$V$2*Data!J12 -> 4480 | AF14: =+$V$2*Data!K12 -> 4480 | AG14: =+$V$2*Data!L12 -> 4480 | AH14: =+$V$2*Data!M12 -> 4480 | AI14: =+$V$2*Data!N12 -> 4480 | AJ14: =+$V$4*Data!O12 -> 133.92
AC15: 55 | AD15: =+$V$2*Data!I13 -> 4440 | AE15: =+$V$2*Data!J13 -> 4440 | AF15: =+$V$2*Data!K13 -> 4440 | AG15: =+$V$2*Data!L13 -> 4440 | AH15: =+$V$2*Data!M13 -> 4440 | AI15: =+$V$2*Data!N13 -> 4440 | AJ15: =+$V$4*Data!O13 -> 132.68
K16: 0.27 | L16: : | M16: =+K16*$M$2 -> 13.5 | O16: =+M16/4*1000 -> 3375 | Q16: =+((O16/$V$2)^1.25)*$V$4 -> 100.27413 | T16: =IF(Q16>=$V$4*110%,"CONSULT TO BS","OK") -> OK | V16: =IF(O16>=$V$2*1.15,"Over Load","OK") -> OK | X16: =IF(Q16<=$V$4*110%,"OK",((Q16-$V$4)/$V$4)) -> OK | Z16: =IF(O16<=$V$2*115%,"OK",((O16-$V$2)/$V$2)) -> OK | AC16: 60 | AD16: =+$V$2*Data!I14 -> 4400 | AE16: =+$V$2*Data!J14 -> 4400 | AF16: =+$V$2*Data!K14 -> 4400 | AG16: =+$V$2*Data!L14 -> 4400 | AH16: =+$V$2*Data!M14 -> 4400 | AI16: =+$V$2*Data!N14 -> 4400 | AJ16: =+$V$4*Data!O14 -> 131.44
AC17: 65 | AD17: =+$V$2*Data!I15 -> 4300 | AE17: =+$V$2*Data!J15 -> 4340 | AF17: =+$V$2*Data!K15 -> 4340 | AG17: =+$V$2*Data!L15 -> 4340 | AH17: =+$V$2*Data!M15 -> 4340 | AI17: =+$V$2*Data!N15 -> 4340 | AJ17: =+$V$4*Data!O15 -> 128.96
AC18: 70 | AD18: =+$V$2*Data!I16 -> 4200 | AE18: =+$V$2*Data!J16 -> 4280 | AF18: =+$V$2*Data!K16 -> 4280 | AG18: =+$V$2*Data!L16 -> 4280 | AH18: =+$V$2*Data!M16 -> 4280 | AI18: =+$V$2*Data!N16 -> 4280 | AJ18: =+$V$4*Data!O16 -> 126.48
L19: : | M19: =+K19*$M$2 -> 0 | O19: =+M19/4*1000 -> 0 | Q19: =+((O19/$V$2)^1.25)*$V$4 -> 0 | T19: =IF(Q19>=$V$4*110%,"CONSULT TO BS","OK") -> OK | V19: =IF(O19>=$V$2*1.15,"Over Load","OK") -> OK | X19: =IF(Q19<=$V$4*110%,"OK",((Q19-$V$4)/$V$4)) -> OK | Z19: =IF(O19<=$V$2*115%,"OK",((O19-$V$2)/$V$2)) -> OK | AC19: 75 | AD19: =+$V$2*Data!I17 -> 4100 | AE19: =+$V$2*Data!J17 -> 4220 | AF19: =+$V$2*Data!K17 -> 4220 | AG19: =+$V$2*Data!L17 -> 4220 | AH19: =+$V$2*Data!M17 -> 4220 | AI19: =+$V$2*Data!N17 -> 4220 | AJ19: =+$V$4*Data!O17 -> 125.24
AC20: 80 | AD20: =+$V$2*Data!I18 -> 4000 | AE20: =+$V$2*Data!J18 -> 4160 | AF20: =+$V$2*Data!K18 -> 4160 | AG20: =+$V$2*Data!L18 -> 4160 | AH20: =+$V$2*Data!M18 -> 4160 | AI20: =+$V$2*Data!N18 -> 4160 | AJ20: =+$V$4*Data!O18 -> 124
AC21: 85 | AD21: =+$V$2*Data!I19 -> 0 | AE21: =+$V$2*Data!J19 -> 4080 | AF21: =+$V$2*Data!K19 -> 4120 | AG21: =+$V$2*Data!L19 -> 4120 | AH21: =+$V$2*Data!M19 -> 4120 | AI21: =+$V$2*Data!N19 -> 4120 | AJ21: =+$V$4*Data!O19 -> 124
T22: Kind of damage by improper : | AC22: 90 | AD22: =+$V$2*Data!I20 -> 0 | AE22: =+$V$2*Data!J20 -> 4000 | AF22: =+$V$2*Data!K20 -> 4080 | AG22: =+$V$2*Data!L20 -> 4080 | AH22: =+$V$2*Data!M20 -> 4080 | AI22: =+$V$2*Data!N20 -> 4080 | AJ22: =+$V$4*Data!O20 -> 124
T23: I/P | U23: : | AC23: 95 | AD23: =+$V$2*Data!I21 -> 0 | AE23: =+$V$2*Data!J21 -> 0 | AF23: =+$V$2*Data!K21 -> 4040 | AG23: =+$V$2*Data!L21 -> 4040 | AH23: =+$V$2*Data!M21 -> 4040 | AI23: =+$V$2*Data!N21 -> 4040 | AJ23: =+$V$4*Data!O21 -> 124
L24: : | M24: MUST FILL WITH VALUE | AC24: 100 | AD24: =+$V$2*Data!I22 -> 0 | AE24: =+$V$2*Data!J22 -> 0 | AF24: =+$V$2*Data!K22 -> 4000 | AG24: =+$V$2*Data!L22 -> 4000 | AH24: =+$V$2*Data!M22 -> 4000 | AI24: =+$V$2*Data!N22 -> 4000 | AJ24: =+$V$4*Data!O22 -> 124
AC25: 110 | AD25: =+$V$2*Data!I23 -> 0 | AE25: =+$V$2*Data!J23 -> 0 | AF25: =+$V$2*Data!K23 -> 0 | AG25: =+$V$2*Data!L23 -> 4000 | AH25: =+$V$2*Data!M23 -> 4000 | AI25: =+$V$2*Data!N23 -> 4000 | AJ25: =+$V$4*Data!O23 -> 124
AC26: 120 | AD26: =+$V$2*Data!I24 -> 0 | AE26: =+$V$2*Data!J24 -> 0 | AF26: =+$V$2*Data!K24 -> 0 | AG26: =+$V$2*Data!L24 -> 0 | AH26: =+$V$2*Data!M24 -> 4000 | AI26: =+$V$2*Data!N24 -> 4000 | AJ26: =+$V$4*Data!O24 -> 124
AC27: 130 | AD27: =+$V$2*Data!I25 -> 0 | AE27: =+$V$2*Data!J25 -> 0 | AF27: =+$V$2*Data!K25 -> 0 | AG27: =+$V$2*Data!L25 -> 0 | AH27: =+$V$2*Data!M25 -> 0 | AI27: =+$V$2*Data!N25 -> 4000 | AJ27: =+$V$4*Data!O25 -> 124
T31: Tire size / Pattern | U31: : | V31: 10.00-20 16 SUTA | W31: Speed Symbol | AD31: Variasi Kapasitas Pembebanan (%) | AJ31: Kompensasi Tekanan Angin %
K32: Total Load | L32: : | M32: 35 | T32: Load Index | U32: : | V32: =+VLOOKUP(V31,Data!$B$2:$D$50,2,FALSE) -> 2754 | W32: =+VLOOKUP(V31,Data!$B$2:$E$50,4,FALSE) -> J | AD32: Simbol Kecepatan
Q33: =+Q3 -> I/P by ETRTO | T33: Ave. Speed | U33: : | V33: 50 | X33: Possibility Tire Damage by : | AD33: F | AE33: G | AF33: J | AG33: K | AH33: L | AI33: M
K34: =+K4 -> Load Distribution | O34: =+O4 -> Load/Tire | T34: STD I/P | U34: : | V34: =+VLOOKUP(V31,Data!$B$2:$E$30,3,FALSE) -> 112 | AC34: 0 | AD34: =+$V$32*Data!I2 -> 6885 | AE34: =+$V$32*Data!J2 -> 6885 | AF34: =+$V$32*Data!K2 -> 6885 | AG34: =+$V$32*Data!L2 -> 6885 | AH34: =+$V$32*Data!M2 -> 6885 | AI34: =+$V$32*Data!N2 -> 6885 | AJ34: =+$V$34*Data!O2 -> 156.8
T35: Result I/P | V35: Result Load | X35: I/P | Z35: Load | AC35: 5 | AD35: =+$V$32*Data!I3 -> 5783.4 | AE35: =+$V$32*Data!J3 -> 5783.4 | AF35: =+$V$32*Data!K3 -> 5783.4 | AG35: =+$V$32*Data!L3 -> 5783.4 | AH35: =+$V$32*Data!M3 -> 5783.4 | AI35: =+$V$32*Data!N3 -> 5783.4 | AJ35: =+$V$34*Data!O3 -> 156.8
K36: 0.18 | L36: : | M36: =+K36*$M$32 -> 6.3 | O36: =+M36/2*1000 -> 3150 | Q36: =+((O36/$V$32)^1.25)*$V$34 -> 132.4803 | T36: =IF(Q36>=$V$34*110%,"CONSULT TO BS","OK") -> CONSULT TO BS | V36: =IF(O36>=$V$32*115%,"Over Load","OK") -> OK | X36: =IF(Q36<=$V$34*110%,"OK",((Q36-$V$34)/$V$34)) -> 0.1828598 | Z36: =IF(O36<=$V$32*115%,"OK",((O36-$V$32)/$V$32)) -> OK | AC36: 10 | AD36: =+$V$32*Data!I4 -> 4957.2 | AE36: =+$V$32*Data!J4 -> 4957.2 | AF36: =+$V$32*Data!K4 -> 4957.2 | AG36: =+$V$32*Data!L4 -> 4957.2 | AH36: =+$V$32*Data!M4 -> 4957.2 | AI36: =+$V$32*Data!N4 -> 4957.2 | AJ36: =+$V$34*Data!O4 -> 145.6
AC37: 15 | AD37: =+$V$32*Data!I5 -> 4544.1 | AE37: =+$V$32*Data!J5 -> 4544.1 | AF37: =+$V$32*Data!K5 -> 4544.1 | AG37: =+$V$32*Data!L5 -> 4544.1 | AH37: =+$V$32*Data!M5 -> 4544.1 | AI37: =+$V$32*Data!N5 -> 4544.1 | AJ37: =+$V$34*Data!O5 -> 140
AC38: 20 | AD38: =+$V$32*Data!I6 -> 4131 | AE38: =+$V$32*Data!J6 -> 4131 | AF38: =+$V$32*Data!K6 -> 4131 | AG38: =+$V$32*Data!L6 -> 4131 | AH38: =+$V$32*Data!M6 -> 4131 | AI38: =+$V$32*Data!N6 -> 4131 | AJ38: =+$V$34*Data!O6 -> 135.52
AC39: 25 | AD39: =+$V$32*Data!I7 -> 3717.9 | AE39: =+$V$32*Data!J7 -> 3717.9 | AF39: =+$V$32*Data!K7 -> 3717.9 | AG39: =+$V$32*Data!L7 -> 3717.9 | AH39: =+$V$32*Data!M7 -> 3717.9 | AI39: =+$V$32*Data!N7 -> 3717.9 | AJ39: =+$V$34*Data!O7 -> 131.04
K40: 0.42 | L40: : | M40: =+K40*$M$32 -> 14.7 | O40: =+M40/4*1000 -> 3675 | Q40: =+((O40/$V$32)^1.25)*$V$34 -> 160.633 | T40: =IF(Q40>=$V$34*110%,"CONSULT TO BS","OK") -> CONSULT TO BS | V40: =IF(O40>=$V$32*115%,"Over Load","OK") -> Over Load | X40: =IF(Q40<=$V$34*110%,"OK",((Q40-$V$34)/$V$34)) -> 0.43422325 | Z40: =IF(O40<=$V$32*115%,"OK",((O40-$V$32)/$V$32)) -> 0.33442266 | AC40: 30 | AD40: =+$V$32*Data!I8 -> 3442.5 | AE40: =+$V$32*Data!J8 -> 3442.5 | AF40: =+$V$32*Data!K8 -> 3442.5 | AG40: =+$V$32*Data!L8 -> 3442.5 | AH40: =+$V$32*Data!M8 -> 3442.5 | AI40: =+$V$32*Data!N8 -> 3442.5 | AJ40: =+$V$34*Data!O8 -> 126.56
AC41: 35 | AD41: =+$V$32*Data!I9 -> 3277.26 | AE41: =+$V$32*Data!J9 -> 3277.26 | AF41: =+$V$32*Data!K9 -> 3277.26 | AG41: =+$V$32*Data!L9 -> 3277.26 | AH41: =+$V$32*Data!M9 -> 3277.26 | AI41: =+$V$32*Data!N9 -> 3277.26 | AJ41: =+$V$34*Data!O9 -> 124.32
AC42: 40 | AD42: =+$V$32*Data!I10 -> 3167.1 | AE42: =+$V$32*Data!J10 -> 3167.1 | AF42: =+$V$32*Data!K10 -> 3167.1 | AG42: =+$V$32*Data!L10 -> 3167.1 | AH42: =+$V$32*Data!M10 -> 3167.1 | AI42: =+$V$32*Data!N10 -> 3167.1 | AJ42: =+$V$34*Data!O10 -> 123.2
K43: 0.4 | L43: : | M43: =+K43*$M$32 -> 14 | O43: =+M43/4*1000 -> 3500 | Q43: =+((O43/$V$32)^1.25)*$V$34 -> 151.12912 | T43: =IF(Q43>=$V$34*110%,"CONSULT TO BS","OK") -> CONSULT TO BS | V43: =IF(O43>=$V$32*115%,"Over Load","OK") -> Over Load | X43: =IF(Q43<=$V$34*110%,"OK",((Q43-$V$34)/$V$34)) -> 0.34936716 | Z43: =IF(O43<=$V$32*115%,"OK",((O43-$V$32)/$V$32)) -> 0.27087872 | AC43: 45 | AD43: =+$V$32*Data!I11 -> 3112.02 | AE43: =+$V$32*Data!J11 -> 3112.02 | AF43: =+$V$32*Data!K11 -> 3112.02 | AG43: =+$V$32*Data!L11 -> 3112.02 | AH43: =+$V$32*Data!M11 -> 3112.02 | AI43: =+$V$32*Data!N11 -> 3112.02 | AJ43: =+$V$34*Data!O11 -> 122.08
...

Sheet Data
A1: NO | B1: TIRE Size | C1: LOAD INDEX | D1: STD I/P | E1: Speed symbol | H1: speed | I1: F | J1: G | K1: J | L1: K | M1: L | N1: M | O1: I/P %
A2: 1 | B2: 9.00-20 14 EMSA | C2: 2575 | D2: 110 | E2: J | H2: 0 | I2: 2.5 | J2: 2.5 | K2: 2.5 | L2: 2.5 | M2: 2.5 | N2: 2.5 | O2: 1.4
B3: 10.00-20 16 EMSA | C3: 3000 | D3: 115 | E3: J | H3: 5 | I3: 2.1 | J3: 2.1 | K3: 2.1 | L3: 2.1 | M3: 2.1 | N3: 2.1 | O3: 1.4
B4: 10.00-20 16 SUTA | C4: 2754 | D4: 112 | E4: J | H4: 10 | I4: 1.8 | J4: 1.8 | K4: 1.8 | L4: 1.8 | M4: 1.8 | N4: 1.8 | O4: 1.3
B5: 10.00-20 16 VLGN | C5: 2700 | D5: 110 | E5: J | H5: 15 | I5: 1.65 | J5: 1.65 | K5: 1.65 | L5: 1.65 | M5: 1.65 | N5: 1.65 | O5: 1.25
B6: 10.00-20 16 ULN | C6: 3000 | D6: 115 | E6: J | H6: 20 | I6: 1.5 | J6: 1.5 | K6: 1.5 | L6: 1.5 | M6: 1.5 | N6: 1.5 | O6: 1.21
B7: 11.00-20 16 EMSA | C7: 3350 | D7: 115 | E7: J | H7: 25 | I7: 1.35 | J7: 1.35 | K7: 1.35 | L7: 1.35 | M7: 1.35 | N7: 1.35 | O7: 1.17
B8: 11.00-20 16 VLGN | C8: 2950 | D8: 110 | E8: J | H8: 30 | I8: 1.25 | J8: 1.25 | K8: 1.25 | L8: 1.25 | M8: 1.25 | N8: 1.25 | O8: 1.13
B9: 11.00-20 18 VLGN | C9: 3000 | D9: 112 | E9: J | H9: 35 | I9: 1.19 | J9: 1.19 | K9: 1.19 | L9: 1.19 | M9: 1.19 | N9: 1.19 | O9: 1.11
B10: 11.00-20 16 UTB | C10: 2950 | D10: 112 | E10: J | H10: 40 | I10: 1.15 | J10: 1.15 | K10: 1.15 | L10: 1.15 | M10: 1.15 | N10: 1.15 | O10: 1.1
B11: 10.00R20 16 R150 | C11: 3000 | D11: 116 | E11: K | H11: 45 | I11: 1.13 | J11: 1.13 | K11: 1.13 | L11: 1.13 | M11: 1.13 | N11: 1.13 | O11: 1.09
B12: 10.00R20 16 M840 | C12: 3075 | D12: 116 | E12: K | H12: 50 | I12: 1.12 | J12: 1.12 | K12: 1.12 | L12: 1.12 | M12: 1.12 | N12: 1.12 | O12: 1.08
B13: 10.00R20 16 M857 | C13: 3075 | D13: 116 | E13: K | H13: 55 | I13: 1.11 | J13: 1.11 | K13: 1.11 | L13: 1.11 | M13: 1.11 | N13: 1.11 | O13: 1.07
B14: 10.00R20 16 L301 | C14: 3075 | D14: 116 | E14: G | H14: 60 | I14: 1.1 | J14: 1.1 | K14: 1.1 | L14: 1.1 | M14: 1.1 | N14: 1.1 | O14: 1.06
... B18: 11.00R20 16 L355 | C18: 3350 | D18: 121 | E18: G | H18: 80 | I18: 1 | J18: 1.04 | K18: 1.04 | L18: 1.04 | M18: 1.04 | N18: 1.04 | O18: 1
B19: 11.00R20 16 L317 | C19: 3550 | D19: 120 | E19: G | H19: 85 | J19: 1.02 | K19: 1.03 | L19: 1.03 | M19: 1.03 | N19: 1.03 | O19: 1
B20: 11R22.5 16 G611 | C20: 3150 | D20: 123 | E20: L | H20: 90 | J20: 1 | K20: 1.02 | L20: 1.02 | M20: 1.02 | N20: 1.02 | O20: 1
B21: 11R22.5 16 R150 | C21: 3150 | D21: 123 | E21: L | H21: 95 | K21: 1.01 | L21: 1.01 | M21: 1.01 | N21: 1.01 | O21: 1
B22: 11R22.5 16 M729 | C22: 3150 | D22: 123 | E22: L | H22: 100 | K22: 1 | L22: 1 | M22: 1 | N22: 1 | O22: 1
B23: 11R22.5 16 M711 | C23: 3150 | D23: 123 | E23: L | H23: 110 | L23: 1 | M23: 1 | N23: 1 | O23: 1
B24: 11R22.5 16 M840 | C24: 3150 | D24: 124 | E24: L | H24: 120 | M24: 1 | N24: 1 | O24: 1
B25: 11R22.5 16 L355 | C25: 3150 | D25: 124 | E25: G | H25: 130 | N25: 1 | O25: 1
B26: 11R22.5 16 L317 | C26: 3150 | D26: 123 | E26: G
B27: 12.00R24 18 M840 | C27: 4000 | D27: 114 | E27: K
B28: 12.00R24 18 L355 | C28: 4000 | D28: 114 | E28: G
B29: 12.00R24 18 L317 | C29: 4000 | D29: 124 | E29: G
B30: 12.00-24 18 VLGN | C30: 3750 | D30: 112 | E30: J

Sheet Sheet2
